<sdf version='1.7'>
  <world name='oceans_waves'>
    <physics name='default_physics' default='1' type='ode'>
      <max_step_size>0.002</max_step_size>
      <real_time_factor>1</real_time_factor>
      <real_time_update_rate>500</real_time_update_rate>
    </physics>
    <scene>
      <ambient>0.01 0.01 0.01 1</ambient>
      <sky>
        <clouds>
          <speed>12</speed>
        </clouds>
      </sky>
      <shadows>1</shadows>
      <background>0.7 0.7 0.7 1</background>
    </scene>
    <spherical_coordinates>
      <latitude_deg>56.719</latitude_deg>
      <longitude_deg>3.51562</longitude_deg>
      <surface_model>EARTH_WGS84</surface_model>
      <elevation>0</elevation>
      <heading_deg>0</heading_deg>
    </spherical_coordinates>
    <light name='sun1' type='directional'>
      <pose>50 0 150 0 -0 0</pose>
      <diffuse>1 1 1 1</diffuse>
      <specular>0.1 0.1 0.1 1</specular>
      <direction>0.3 0.3 -1</direction>
      <cast_shadows>0</cast_shadows>
      <attenuation>
        <range>10</range>
      </attenuation>
      <spot>
        <inner_angle>0</inner_angle>
        <outer_angle>0</outer_angle>
        <falloff>0</falloff>
      </spot>
    </light>
    <light name='sun_diffuse' type='directional'>
      <pose>-50 0 -150 0 -0 0</pose>
      <diffuse>0.6 0.6 0.6 1</diffuse>
      <specular>0 0 0 1</specular>
      <direction>-0.3 -0.3 -1</direction>
      <cast_shadows>0</cast_shadows>
      <attenuation>
        <range>10</range>
      </attenuation>
      <spot>
        <inner_angle>0</inner_angle>
        <outer_angle>0</outer_angle>
        <falloff>0</falloff>
      </spot>
    </light>
    <model name='world_ned'>
      <pose>0 0 0 0 -0 0</pose>
      <static>1</static>
      <link name='world_ned'>
        <gravity>0</gravity>
        <pose>0 0 0 -3.14159 -0 1.5708</pose>
        <visual name='N_visual'>
          <pose>0.25 0 0 1.5708 -0 1.5708</pose>
          <geometry>
            <cylinder>
              <radius>0.01</radius>
              <length>0.5</length>
            </cylinder>
          </geometry>
          <material>
            <script>
              <uri>file://media/materials/scripts/gazebo.material</uri>
              <name>Gazebo/Red</name>
            </script>
          </material>
        </visual>
        <visual name='E_visual'>
          <pose>0 0.25 0 1.5708 -0 0</pose>
          <geometry>
            <cylinder>
              <radius>0.01</radius>
              <length>0.5</length>
            </cylinder>
          </geometry>
          <material>
            <script>
              <uri>file://media/materials/scripts/gazebo.material</uri>
              <name>Gazebo/Green</name>
            </script>
          </material>
        </visual>
        <visual name='D_visual'>
          <pose>0 0 0.25 0 -0 0</pose>
          <geometry>
            <cylinder>
              <radius>0.01</radius>
              <length>0.5</length>
            </cylinder>
          </geometry>
          <material>
            <script>
              <uri>file://media/materials/scripts/gazebo.material</uri>
              <name>Gazebo/Blue</name>
            </script>
          </material>
        </visual>
        <self_collide>0</self_collide>
        <enable_wind>0</enable_wind>
        <kinematic>0</kinematic>
      </link>
    </model>
    <model name='ocean'>
      <static>1</static>
      <link name='ocean_link'>
        <visual name='ocean_surface'>
          <pose>0 0 0 0 -0 0</pose>
          <cast_shadows>0</cast_shadows>
          <geometry>
            <mesh>
              <uri>file://Media/models/sea_surface_1000m_x_1000m.dae</uri>
              <scale>2 2 2</scale>
            </mesh>
          </geometry>
          <material>
            <script>
              <uri>file://Media/materials/scripts/waves.material</uri>
              <name>UUVSimulator/SimpleWaves</name>
            </script>
          </material>
        </visual>
        <visual name='ocean_below'>
          <pose>0 0 0 3.14 -0 0</pose>
          <cast_shadows>0</cast_shadows>
          <geometry>
            <mesh>
              <uri>file://Media/models/sea_surface_1000m_x_1000m.dae</uri>
              <scale>2 2 2</scale>
            </mesh>
          </geometry>
          <material>
            <script>
              <uri>file://Media/materials/scripts/water.material</uri>
              <name>UUVSimulator/StaticWater</name>
            </script>
          </material>
        </visual>
        <visual name='seafloor'>
          <cast_shadows>0</cast_shadows>
          <pose>0 0 -100 0 -0 0</pose>
          <geometry>
            <box>
              <size>2000 2000 0.1</size>
            </box>
          </geometry>
          <material>
            <script>
              <uri>file://Media/materials/scripts/sand.material</uri>
              <name>UUVSimulator/SandAndStones</name>
            </script>
            <emissive>0.6 0.6 0.6 1</emissive>
          </material>
        </visual>
        <collision name='seafloor'>
          <pose>0 0 -100 0 -0 0</pose>
          <geometry>
            <box>
              <size>2000 2000 0.1</size>
            </box>
          </geometry>
          <max_contacts>10</max_contacts>
          <surface>
            <contact>
              <ode/>
            </contact>
            <bounce/>
            <friction>
              <torsional>
                <ode/>
              </torsional>
              <ode/>
            </friction>
          </surface>
        </collision>
        <visual name='north'>
          <pose>1000 0 -50 3.14159 -1.57079 3.14159</pose>
          <geometry>
            <plane>
              <normal>0 0 1</normal>
              <size>100 2000</size>
            </plane>
          </geometry>
          <material>
            <script>
              <uri>file://Media/materials/scripts/water.material</uri>
              <name>UUVSimulator/SeaWall</name>
            </script>
            <emissive>0.6 0.6 0.6 1</emissive>
          </material>
        </visual>
        <visual name='south'>
          <pose>-1000 0 -50 3.14159 1.57079 3.14159</pose>
          <geometry>
            <plane>
              <normal>0 0 1</normal>
              <size>100 2000</size>
            </plane>
          </geometry>
          <material>
            <script>
              <uri>file://Media/materials/scripts/water.material</uri>
              <name>UUVSimulator/SeaWall</name>
            </script>
            <emissive>0.6 0.6 0.6 1</emissive>
          </material>
        </visual>
        <visual name='west'>
          <pose>0 1000 -50 1.5708 -0 0</pose>
          <geometry>
            <plane>
              <normal>0 0 1</normal>
              <size>2000 100</size>
            </plane>
          </geometry>
          <material>
            <script>
              <uri>file://Media/materials/scripts/water.material</uri>
              <name>UUVSimulator/SeaWall</name>
            </script>
            <emissive>0.6 0.6 0.6 1</emissive>
          </material>
        </visual>
        <visual name='east'>
          <pose>0 -1000 -50 -1.5708 0 0</pose>
          <geometry>
            <plane>
              <normal>0 0 1</normal>
              <size>2000 100</size>
            </plane>
          </geometry>
          <material>
            <script>
              <uri>file://Media/materials/scripts/water.material</uri>
              <name>UUVSimulator/SeaWall</name>
            </script>
            <emissive>0.6 0.6 0.6 1</emissive>
          </material>
        </visual>
        <self_collide>0</self_collide>
        <enable_wind>0</enable_wind>
        <kinematic>0</kinematic>
      </link>
      <pose>0 0 0 0 -0 0</pose>
    </model>
    <model name='sea_bottom'>
      <static>1</static>
      <link name='sea_bottom'>
        <collision name='collision'>
          <pose>0 0 0 0 -0 0</pose>
          <geometry>
            <box>
              <size>2000 2000 0.1</size>
            </box>
          </geometry>
          <max_contacts>10</max_contacts>
          <surface>
            <contact>
              <ode/>
            </contact>
            <bounce/>
            <friction>
              <torsional>
                <ode/>
              </torsional>
              <ode/>
            </friction>
          </surface>
        </collision>
        <visual name='visual'>
          <cast_shadows>0</cast_shadows>
          <pose>0 0 0 0 -0 0</pose>
          <geometry>
            <box>
              <size>2000 2000 0.1</size>
            </box>
          </geometry>
          <material>
            <script>
              <uri>file://Media/materials/scripts/sand.material</uri>
              <name>UUVSimulator/SandAndStones</name>
            </script>
            <emissive>0.2 0.2 0.2 1</emissive>
          </material>
        </visual>
        <self_collide>0</self_collide>
        <enable_wind>0</enable_wind>
        <kinematic>0</kinematic>
      </link>
      <pose>0 0 -35 0 -0 0</pose>
    </model>
    <plugin name='underwater_current_plugin' filename='libuuv_underwater_current_ros_plugin.so'>
      <namespace>hydrodynamics</namespace>
      <constant_current>
        <topic>current_velocity</topic>
        <velocity>
          <mean>0</mean>
          <min>0</min>
          <max>5</max>
          <mu>0.0</mu>
          <noiseAmp>0.0</noiseAmp>
        </velocity>
        <horizontal_angle>
          <mean>0</mean>
          <min>-3.141592653589793238</min>
          <max>3.141592653589793238</max>
          <mu>0.0</mu>
          <noiseAmp>0.0</noiseAmp>
        </horizontal_angle>
        <vertical_angle>
          <mean>0</mean>
          <min>-3.141592653589793238</min>
          <max>3.141592653589793238</max>
          <mu>0.0</mu>
          <noiseAmp>0.0</noiseAmp>
        </vertical_angle>
      </constant_current>
    </plugin>
    <plugin name='sc_interface' filename='libuuv_sc_ros_interface_plugin.so'/>
    <gui fullscreen='0'>
      <camera name='user_camera'>
        <pose>18.8086 -11.3398 -17.4755 0 0.482561 2.94466</pose>
        <view_controller>orbit</view_controller>
        <projection_type>perspective</projection_type>
      </camera>
    </gui>
    <gravity>0 0 -9.8</gravity>
    <magnetic_field>6e-06 2.3e-05 -4.2e-05</magnetic_field>
    <atmosphere type='adiabatic'/>
    <wind/>
    <model name='Marker0'>
      <static>1</static>
      <link name='link'>
        <visual name='visual'>
          <geometry>
            <mesh>
              <uri>model://marker0/meshes/Marker0.dae</uri>
              <scale>6 6 6</scale>
            </mesh>
          </geometry>
        </visual>
        <self_collide>0</self_collide>
        <enable_wind>0</enable_wind>
        <kinematic>0</kinematic>
      </link>
      <pose>-18 -7 -23 0 -0 0</pose>
    </model>
    <state world_name='oceans_waves'>
      <sim_time>353 824000000</sim_time>
      <real_time>450 546371214</real_time>
      <wall_time>1713515879 840844183</wall_time>
      <iterations>131435</iterations>
      <model name='Marker0'>
        <pose>-5.06799 -2.46516 -35 0 -0 0</pose>
        <scale>1 1 1</scale>
        <link name='link'>
          <pose>-5.06799 -2.46516 -35 0 -0 0</pose>
          <velocity>0 0 0 0 -0 0</velocity>
          <acceleration>0 0 0 0 -0 0</acceleration>
          <wrench>0 0 0 0 -0 0</wrench>
        </link>
      </model>
      <model name='bluerov2'>
        <pose>-12.763 -2.52656 -34.7607 0.000855 0.003433 -0.024222</pose>
        <scale>1 1 1</scale>
        <link name='/camera_front_link'>
          <pose>-12.5631 -2.5314 -34.7614 0.000855 0.003433 -0.024222</pose>
          <velocity>-0.00036 -0.00039 0.00048 0.001521 -0.000261 -0.00016</velocity>
          <acceleration>0.004224 0.003195 -0.237117 -0.275251 0.784061 0.013095</acceleration>
          <wrench>4e-06 3e-06 -0.000237 0 -0 0</wrench>
        </link>
        <link name='/camera_front_link_optical'>
          <pose>-12.5631 -2.5314 -34.7614 -1.57423 0.000855 -1.59502</pose>
          <velocity>-0.00036 -0.00039 0.00048 0.001521 -0.000261 -0.00016</velocity>
          <acceleration>0.004224 0.003195 -0.237118 -0.275251 0.784061 0.013095</acceleration>
          <wrench>4e-06 3e-06 -0.000237 0 -0 0</wrench>
        </link>
        <link name='bluerov2/base_link'>
          <pose>-12.763 -2.52656 -34.7607 0.000855 0.003433 -0.024222</pose>
          <velocity>-0.00036 -0.000359 0.000436 0.001521 -0.000261 -0.00016</velocity>
          <acceleration>0.004701 0.000768 -0.081686 -0.283126 0.784147 0.013085</acceleration>
          <wrench>0.052648 0.008597 -0.914878 0 -0 0</wrench>
        </link>
        <link name='bluerov2/gps_link'>
          <pose>-12.763 -2.52656 -34.7607 0.000855 0.003433 -0.024222</pose>
          <velocity>-0.00036 -0.000359 0.000436 0.001521 -0.000261 -0.00016</velocity>
          <acceleration>0.0047 0.000767 -0.081685 -0.275251 0.784061 0.013095</acceleration>
          <wrench>5e-06 1e-06 -8.2e-05 0 -0 0</wrench>
        </link>
        <link name='bluerov2/imu_link'>
          <pose>-12.763 -2.52656 -34.7607 0.000855 0.003433 -0.024222</pose>
          <velocity>-0.00036 -0.000359 0.000436 0.001521 -0.000261 -0.00016</velocity>
          <acceleration>0.0047 0.000767 -0.081685 -0.275251 0.784061 0.013095</acceleration>
          <wrench>7.1e-05 1.2e-05 -0.001225 0 -0 0</wrench>
        </link>
        <link name='bluerov2/pose_sensor_link_default'>
          <pose>-12.763 -2.52656 -34.7607 0.000855 0.003433 -0.024222</pose>
          <velocity>-0.00036 -0.000359 0.000436 0.001521 -0.000261 -0.00016</velocity>
          <acceleration>0.0047 0.000767 -0.081685 -0.275251 0.784061 0.013095</acceleration>
          <wrench>5e-06 1e-06 -8.2e-05 0 -0 0</wrench>
        </link>
        <link name='bluerov2/pressure_link'>
          <pose>-12.763 -2.52656 -34.7607 0.000855 0.003433 -0.024222</pose>
          <velocity>-0.00036 -0.000359 0.000436 0.001521 -0.000261 -0.00016</velocity>
          <acceleration>0.0047 0.000767 -0.081685 -0.275251 0.784061 0.013095</acceleration>
          <wrench>7.1e-05 1.2e-05 -0.001225 0 -0 0</wrench>
        </link>
        <link name='bluerov2/sonarforward_link'>
          <pose>-12.5633 -2.53136 -34.8114 0.000855 0.003433 -0.024222</pose>
          <velocity>-0.000347 -0.000313 0.00048 0.001521 -0.000261 -0.00016</velocity>
          <acceleration>-0.034979 -0.010569 -0.236996 -0.275251 0.784061 0.013095</acceleration>
          <wrench>-0.003498 -0.001057 -0.0237 0 -0 0</wrench>
        </link>
        <link name='bluerov2/thruster_0'>
          <pose>-12.6302 -2.62974 -34.8338 0.00303 0.001823 0.761178</pose>
          <velocity>-0.000357 -0.000269 0.000313 0.001026 -0.000732 -0.000158</velocity>
          <acceleration>-0.051224 -0.0176 -0.157399 -0.522512 0.548492 0.013719</acceleration>
          <wrench>-0.000512 -0.000176 -0.001574 0 -0 0</wrench>
        </link>
        <link name='bluerov2/thruster_1'>
          <pose>-12.6254 -2.4298 -34.8336 -0.001825 0.003032 -0.809624</pose>
          <velocity>-0.000325 -0.00027 0.000619 0.002566 -0.001358 -0.000164</velocity>
          <acceleration>-0.053709 -0.01749 -0.216231 0.247303 0.235557 0.010801</acceleration>
          <wrench>-0.000537 -0.000175 -0.002162 0 -0 0</wrench>
        </link>
        <link name='bluerov2/thruster_2'>
          <pose>-12.9132 -2.62289 -34.8328 0.001825 -0.003032 2.33196</pose>
          <velocity>-0.000356 -0.000225 0.00025 0.002566 -0.001358 -0.000164</velocity>
          <acceleration>-0.050551 -0.021038 0.062537 0.247302 0.235553 0.010801</acceleration>
          <wrench>-0.000506 -0.00021 0.000625 0 -0 0</wrench>
        </link>
        <link name='bluerov2/thruster_3'>
          <pose>-12.9083 -2.42295 -34.8326 -0.00303 -0.001823 -2.38041</pose>
          <velocity>-0.000324 -0.000226 0.000555 0.001026 -0.000732 -0.000158</velocity>
          <acceleration>-0.053036 -0.020928 0.003705 -0.522513 0.548489 0.013719</acceleration>
          <wrench>-0.00053 -0.000209 3.7e-05 0 -0 0</wrench>
        </link>
        <link name='bluerov2/thruster_4'>
          <pose>-12.7632 -2.63708 -34.7658 0.244347 -1.56726 -0.26857</pose>
          <velocity>-0.000376 -0.000351 0.000267 0.00152 -0.000261 -0.000182</velocity>
          <acceleration>0.002147 -0.000639 -0.051112 -0.275287 0.78407 0.001671</acceleration>
          <wrench>2.1e-05 -6e-06 -0.000511 0 -0 0</wrench>
        </link>
        <link name='bluerov2/thruster_5'>
          <pose>-12.7579 -2.41615 -34.7656 0.244347 -1.56726 -0.26857</pose>
          <velocity>-0.000341 -0.000352 0.000605 0.00152 -0.000261 -0.000182</velocity>
          <acceleration>-0.000599 -0.000518 -0.116121 -0.275287 0.78407 0.001671</acceleration>
          <wrench>-6e-06 -5e-06 -0.001161 0 -0 0</wrench>
        </link>
      </model>
      <model name='ocean'>
        <pose>0 0 0 0 -0 0</pose>
        <scale>1 1 1</scale>
        <link name='ocean_link'>
          <pose>0 0 0 0 -0 0</pose>
          <velocity>0 0 0 0 -0 0</velocity>
          <acceleration>0 0 0 0 -0 0</acceleration>
          <wrench>0 0 0 0 -0 0</wrench>
        </link>
      </model>
      <model name='sea_bottom'>
        <pose>0 0 -35 0 -0 0</pose>
        <scale>1 1 1</scale>
        <link name='sea_bottom'>
          <pose>0 0 -35 0 -0 0</pose>
          <velocity>0 0 0 0 -0 0</velocity>
          <acceleration>0 0 0 0 -0 0</acceleration>
          <wrench>0 0 0 0 -0 0</wrench>
        </link>
      </model>
      <model name='swimming_pool_bigger'>
        <pose>0 0 -35 0 -0 0</pose>
        <scale>1 1 1</scale>
        <link name='Wall_5'>
          <pose>-15.5179 0 -35 0 -0 1.5708</pose>
          <velocity>0 0 0 0 -0 0</velocity>
          <acceleration>0 0 0 0 -0 0</acceleration>
          <wrench>0 0 0 0 -0 0</wrench>
        </link>
        <link name='Wall_6'>
          <pose>-2.46791 5.55 -35 0 -0 0</pose>
          <velocity>0 0 0 0 -0 0</velocity>
          <acceleration>0 0 0 0 -0 0</acceleration>
          <wrench>0 0 0 0 -0 0</wrench>
        </link>
        <link name='Wall_7'>
          <pose>10.5821 0 -35 0 0 -1.5708</pose>
          <velocity>0 0 0 0 -0 0</velocity>
          <acceleration>0 0 0 0 -0 0</acceleration>
          <wrench>0 0 0 0 -0 0</wrench>
        </link>
        <link name='Wall_9'>
          <pose>-2.59291 -5.55 -35 0 -0 3.14159</pose>
          <velocity>0 0 0 0 -0 0</velocity>
          <acceleration>0 0 0 0 -0 0</acceleration>
          <wrench>0 0 0 0 -0 0</wrench>
        </link>
      </model>
      <model name='world_ned'>
        <pose>0 0 0 0 -0 0</pose>
        <scale>1 1 1</scale>
        <link name='world_ned'>
          <pose>0 0 0 -3.14159 -0 1.5708</pose>
          <velocity>0 0 0 0 -0 0</velocity>
          <acceleration>0 0 0 0 -0 0</acceleration>
          <wrench>0 0 0 0 -0 0</wrench>
        </link>
      </model>
      <light name='sun1'>
        <pose>50 0 150 0 -0 0</pose>
      </light>
      <light name='sun_diffuse'>
        <pose>-50 0 -150 0 -0 0</pose>
      </light>
    </state>
    <model name='swimming_pool_bigger'>
      <pose>-15.5929 -3.32555 0 0 -0 0</pose>
      <link name='Wall_5'>
        <collision name='Wall_5_Collision'>
          <geometry>
            <box>
              <size>11.25 0.15 2.5</size>
            </box>
          </geometry>
          <pose>0 0 1.25 0 -0 0</pose>
          <max_contacts>10</max_contacts>
          <surface>
            <contact>
              <ode/>
            </contact>
            <bounce/>
            <friction>
              <torsional>
                <ode/>
              </torsional>
              <ode/>
            </friction>
          </surface>
        </collision>
        <visual name='Wall_5_Visual'>
          <pose>0 0 1.25 0 -0 0</pose>
          <geometry>
            <box>
              <size>11.25 0.15 2.5</size>
            </box>
          </geometry>
          <material>
            <script>
              <uri>file://media/materials/scripts/gazebo.material</uri>
              <name>Gazebo/Grey</name>
            </script>
            <ambient>1 1 1 1</ambient>
          </material>
          <meta>
            <layer>0</layer>
          </meta>
        </visual>
        <pose>-15.5179 0 0 0 -0 1.5708</pose>
        <self_collide>0</self_collide>
        <enable_wind>0</enable_wind>
        <kinematic>0</kinematic>
      </link>
      <link name='Wall_6'>
        <collision name='Wall_6_Collision'>
          <geometry>
            <box>
              <size>26.25 0.15 2.5</size>
            </box>
          </geometry>
          <pose>0 0 1.25 0 -0 0</pose>
          <max_contacts>10</max_contacts>
          <surface>
            <contact>
              <ode/>
            </contact>
            <bounce/>
            <friction>
              <torsional>
                <ode/>
              </torsional>
              <ode/>
            </friction>
          </surface>
        </collision>
        <visual name='Wall_6_Visual'>
          <pose>0 0 1.25 0 -0 0</pose>
          <geometry>
            <box>
              <size>26.25 0.15 2.5</size>
            </box>
          </geometry>
          <material>
            <script>
              <uri>file://media/materials/scripts/gazebo.material</uri>
              <name>Gazebo/Grey</name>
            </script>
            <ambient>1 1 1 1</ambient>
          </material>
          <meta>
            <layer>0</layer>
          </meta>
        </visual>
        <pose>-2.46791 5.55 0 0 -0 0</pose>
        <self_collide>0</self_collide>
        <enable_wind>0</enable_wind>
        <kinematic>0</kinematic>
      </link>
      <link name='Wall_7'>
        <collision name='Wall_7_Collision'>
          <geometry>
            <box>
              <size>11.25 0.15 2.5</size>
            </box>
          </geometry>
          <pose>0 0 1.25 0 -0 0</pose>
          <max_contacts>10</max_contacts>
          <surface>
            <contact>
              <ode/>
            </contact>
            <bounce/>
            <friction>
              <torsional>
                <ode/>
              </torsional>
              <ode/>
            </friction>
          </surface>
        </collision>
        <visual name='Wall_7_Visual'>
          <pose>0 0 1.25 0 -0 0</pose>
          <geometry>
            <box>
              <size>11.25 0.15 2.5</size>
            </box>
          </geometry>
          <material>
            <script>
              <uri>file://media/materials/scripts/gazebo.material</uri>
              <name>Gazebo/Grey</name>
            </script>
            <ambient>1 1 1 1</ambient>
          </material>
          <meta>
            <layer>0</layer>
          </meta>
        </visual>
        <pose>10.5821 0 0 0 -0 -1.5708</pose>
        <self_collide>0</self_collide>
        <enable_wind>0</enable_wind>
        <kinematic>0</kinematic>
      </link>
      <link name='Wall_9'>
        <collision name='Wall_9_Collision'>
          <geometry>
            <box>
              <size>26 0.15 2.5</size>
            </box>
          </geometry>
          <pose>0 0 1.25 0 -0 0</pose>
          <max_contacts>10</max_contacts>
          <surface>
            <contact>
              <ode/>
            </contact>
            <bounce/>
            <friction>
              <torsional>
                <ode/>
              </torsional>
              <ode/>
            </friction>
          </surface>
        </collision>
        <visual name='Wall_9_Visual'>
          <pose>0 0 1.25 0 -0 0</pose>
          <geometry>
            <box>
              <size>26 0.15 2.5</size>
            </box>
          </geometry>
          <material>
            <script>
              <uri>file://media/materials/scripts/gazebo.material</uri>
              <name>Gazebo/Grey</name>
            </script>
            <ambient>1 1 1 1</ambient>
          </material>
          <meta>
            <layer>0</layer>
          </meta>
        </visual>
        <pose>-2.59291 -5.55 0 0 -0 3.14159</pose>
        <self_collide>0</self_collide>
        <enable_wind>0</enable_wind>
        <kinematic>0</kinematic>
      </link>
      <static>1</static>
    </model>
    <model name='bluerov2'>
      <link name='bluerov2/base_link'>
        <inertial>
          <pose>0 0 0 0 -0 0</pose>
          <mass>11.2</mass>
          <inertia>
            <ixx>0.303754</ixx>
            <ixy>0</ixy>
            <ixz>0</ixz>
            <iyy>0.626022</iyy>
            <iyz>0</iyz>
            <izz>0.576886</izz>
          </inertia>
        </inertial>
        <collision name='bluerov2/base_link_collision'>
          <pose>0 0 0 0 -0 0</pose>
          <geometry>
            <mesh>
              <scale>1 1 1</scale>
              <uri>file:///home/ubuntu/34763-autonomous-marine-robotics/ros_ws/src/bluerov2/bluerov2_description/meshes/bluerov2_noprop.stl</uri>
            </mesh>
          </geometry>
          <surface>
            <contact>
              <ode/>
            </contact>
            <friction>
              <ode/>
              <torsional>
                <ode/>
              </torsional>
            </friction>
            <bounce/>
          </surface>
          <max_contacts>10</max_contacts>
        </collision>
        <visual name='bluerov2/base_link_visual'>
          <pose>0 0 0 0 -0 0</pose>
          <geometry>
            <mesh>
              <scale>1 1 1</scale>
              <uri>file:///home/ubuntu/34763-autonomous-marine-robotics/ros_ws/src/bluerov2/bluerov2_description/meshes/bluerov2_noprop.dae</uri>
            </mesh>
          </geometry>
        </visual>
        <self_collide>0</self_collide>
        <enable_wind>0</enable_wind>
        <kinematic>0</kinematic>
      </link>
      <joint name='/camera_front_joint' type='revolute'>
        <pose relative_to='bluerov2/base_link'>0.2 0 0 0 -0 0</pose>
        <parent>bluerov2/base_link</parent>
        <child>/camera_front_link</child>
        <axis>
          <xyz>1 0 0</xyz>
          <limit>
            <lower>0</lower>
            <upper>0</upper>
            <effort>0</effort>
            <velocity>0</velocity>
          </limit>
          <dynamics>
            <spring_reference>0</spring_reference>
            <spring_stiffness>0</spring_stiffness>
          </dynamics>
        </axis>
      </joint>
      <link name='/camera_front_link'>
        <pose relative_to='/camera_front_joint'>0 0 0 0 -0 0</pose>
        <inertial>
          <pose>0 0 0 0 -0 0</pose>
          <mass>0.001</mass>
          <inertia>
            <ixx>1e-05</ixx>
            <ixy>0</ixy>
            <ixz>0</ixz>
            <iyy>1e-05</iyy>
            <iyz>0</iyz>
            <izz>1e-05</izz>
          </inertia>
        </inertial>
        <collision name='/camera_front_link_collision'>
          <pose>0 0 0 3.14159 1.57079 3.14159</pose>
          <geometry>
            <cylinder>
              <length>1e-06</length>
              <radius>1e-06</radius>
            </cylinder>
          </geometry>
          <surface>
            <contact>
              <ode/>
            </contact>
            <friction>
              <ode/>
              <torsional>
                <ode/>
              </torsional>
            </friction>
            <bounce/>
          </surface>
          <max_contacts>10</max_contacts>
        </collision>
        <visual name='/camera_front_link_visual'>
          <pose>0 0 0 0 -0 0</pose>
          <geometry>
            <mesh>
              <scale>1 1 1</scale>
              <uri>file:///home/ubuntu/34763-autonomous-marine-robotics/ros_ws/src/uuv_simulator/uuv_sensor_plugins/uuv_sensor_ros_plugins/meshes/oe14-372.dae</uri>
            </mesh>
          </geometry>
        </visual>
        <sensor name='camera_front' type='camera'>
          <update_rate>30</update_rate>
          <camera name='camera_front'>
            <horizontal_fov>1.5125</horizontal_fov>
            <image>
              <width>1920</width>
              <height>1080</height>
              <format>R8G8B8</format>
            </image>
            <clip>
              <near>0.05</near>
              <far>3000</far>
            </clip>
            <noise>
              <type>gaussian</type>
              <mean>0</mean>
              <stddev>0.01</stddev>
            </noise>
          </camera>
          <plugin name='camera_front_controller' filename='libgazebo_ros_camera.so'>
            <updateRate>30</updateRate>
            <cameraName>camera_front</cameraName>
            <frameName>camera_front_link_optical</frameName>
            <attenuationR>0.0</attenuationR>
            <attenuationG>0.0</attenuationG>
            <attenuationB>0.0</attenuationB>
            <backgroundR>0</backgroundR>
            <backgroundG>0</backgroundG>
            <backgroundB>0</backgroundB>
            <imageTopicName>camera_image</imageTopicName>
            <pointCloudTopicName>camera_cloud</pointCloudTopicName>
            <depthImageTopicName>camera_depth</depthImageTopicName>
            <depthImageCameraInfoTopicName>camera_depth_info</depthImageCameraInfoTopicName>
            <pointCloudCutoff>10.0</pointCloudCutoff>
            <robotNamespace>/bluerov2/</robotNamespace>
          </plugin>
        </sensor>
        <self_collide>0</self_collide>
        <enable_wind>0</enable_wind>
        <kinematic>0</kinematic>
      </link>
      <joint name='/camera_front_optical_joint' type='revolute'>
        <pose relative_to='/camera_front_link'>0 0 0 -1.5708 -0 -1.5708</pose>
        <parent>/camera_front_link</parent>
        <child>/camera_front_link_optical</child>
        <axis>
          <xyz>1 0 0</xyz>
          <limit>
            <lower>0</lower>
            <upper>0</upper>
            <effort>0</effort>
            <velocity>0</velocity>
          </limit>
          <dynamics>
            <spring_reference>0</spring_reference>
            <spring_stiffness>0</spring_stiffness>
          </dynamics>
        </axis>
      </joint>
      <link name='/camera_front_link_optical'>
        <pose relative_to='/camera_front_optical_joint'>0 0 0 0 -0 0</pose>
        <inertial>
          <pose>0 0 0 0 -0 0</pose>
          <mass>0.001</mass>
          <inertia>
            <ixx>1.66667e-12</ixx>
            <ixy>0</ixy>
            <ixz>0</ixz>
            <iyy>1.66667e-12</iyy>
            <iyz>0</iyz>
            <izz>1.66667e-12</izz>
          </inertia>
        </inertial>
        <collision name='/camera_front_link_optical_collision'>
          <pose>0 0 0 3.14159 1.57079 3.14159</pose>
          <geometry>
            <cylinder>
              <length>1e-06</length>
              <radius>1e-06</radius>
            </cylinder>
          </geometry>
          <max_contacts>10</max_contacts>
          <surface>
            <contact>
              <ode/>
            </contact>
            <bounce/>
            <friction>
              <torsional>
                <ode/>
              </torsional>
              <ode/>
            </friction>
          </surface>
        </collision>
        <self_collide>0</self_collide>
        <enable_wind>0</enable_wind>
        <kinematic>0</kinematic>
      </link>
      <joint name='bluerov2/gps_joint' type='revolute'>
        <pose relative_to='bluerov2/base_link'>0 0 0 0 -0 0</pose>
        <parent>bluerov2/base_link</parent>
        <child>bluerov2/gps_link</child>
        <axis>
          <xyz>1 0 0</xyz>
          <limit>
            <lower>0</lower>
            <upper>0</upper>
            <effort>0</effort>
            <velocity>0</velocity>
          </limit>
          <dynamics>
            <spring_reference>0</spring_reference>
            <spring_stiffness>0</spring_stiffness>
          </dynamics>
        </axis>
      </joint>
      <link name='bluerov2/gps_link'>
        <pose relative_to='bluerov2/gps_joint'>0 0 0 0 -0 0</pose>
        <inertial>
          <pose>0 0 0 0 -0 0</pose>
          <mass>0.001</mass>
          <inertia>
            <ixx>1e-05</ixx>
            <ixy>0</ixy>
            <ixz>0</ixz>
            <iyy>1e-05</iyy>
            <iyz>0</iyz>
            <izz>1e-05</izz>
          </inertia>
        </inertial>
        <sensor name='bluerov2/gps' type='gps'>
          <pose>0 0 0 0 -0 0</pose>
          <visualize>0</visualize>
          <always_on>1</always_on>
          <update_rate>30</update_rate>
          <gps>
            <position_sensing>
              <horizontal>
                <noise type='gaussian'>
                  <mean>0</mean>
                  <stddev>0</stddev>
                  <bias_mean>0</bias_mean>
                  <bias_stddev>0</bias_stddev>
                </noise>
              </horizontal>
              <vertical>
                <noise type='gaussian'>
                  <mean>0</mean>
                  <stddev>0</stddev>
                  <bias_mean>0</bias_mean>
                  <bias_stddev>0</bias_stddev>
                </noise>
              </vertical>
            </position_sensing>
            <velocity_sensing>
              <horizontal>
                <noise type='gaussian'>
                  <mean>0</mean>
                  <stddev>0</stddev>
                  <bias_mean>0</bias_mean>
                  <bias_stddev>0</bias_stddev>
                </noise>
              </horizontal>
              <vertical>
                <noise type='gaussian'>
                  <mean>0</mean>
                  <stddev>0</stddev>
                  <bias_mean>0</bias_mean>
                  <bias_stddev>0</bias_stddev>
                </noise>
              </vertical>
            </velocity_sensing>
          </gps>
          <plugin name='bluerov2_gazebo_gps_ros_plugin' filename='libuuv_gazebo_ros_gps_plugin.so'>
            <robot_namespace>bluerov2</robot_namespace>
            <sensor_topic>gps</sensor_topic>
            <horizontal_pos_std_dev>0.0</horizontal_pos_std_dev>
            <vertical_pos_std_dev>0.0</vertical_pos_std_dev>
            <update_rate>30</update_rate>
            <is_on>1</is_on>
            <enable_gazebo_messages>1</enable_gazebo_messages>
            <robotNamespace>/bluerov2/</robotNamespace>
          </plugin>
        </sensor>
        <self_collide>0</self_collide>
        <enable_wind>0</enable_wind>
        <kinematic>0</kinematic>
      </link>
      <joint name='bluerov2/imu_joint' type='revolute'>
        <pose relative_to='bluerov2/base_link'>0 0 0 0 -0 0</pose>
        <parent>bluerov2/base_link</parent>
        <child>bluerov2/imu_link</child>
        <axis>
          <xyz>1 0 0</xyz>
          <limit>
            <lower>0</lower>
            <upper>0</upper>
            <effort>0</effort>
            <velocity>0</velocity>
          </limit>
          <dynamics>
            <spring_reference>0</spring_reference>
            <spring_stiffness>0</spring_stiffness>
          </dynamics>
        </axis>
      </joint>
      <link name='bluerov2/imu_link'>
        <pose relative_to='bluerov2/imu_joint'>0 0 0 0 -0 0</pose>
        <inertial>
          <pose>0 0 0 0 -0 0</pose>
          <mass>0.015</mass>
          <inertia>
            <ixx>1e-05</ixx>
            <ixy>0</ixy>
            <ixz>0</ixz>
            <iyy>1e-05</iyy>
            <iyz>0</iyz>
            <izz>1e-05</izz>
          </inertia>
        </inertial>
        <self_collide>0</self_collide>
        <enable_wind>0</enable_wind>
        <kinematic>0</kinematic>
      </link>
      <joint name='bluerov2/pose_sensor_default_joint' type='revolute'>
        <pose relative_to='bluerov2/base_link'>0 0 0 0 -0 0</pose>
        <parent>bluerov2/base_link</parent>
        <child>bluerov2/pose_sensor_link_default</child>
        <axis>
          <xyz>0 0 1</xyz>
          <limit>
            <lower>0</lower>
            <upper>0</upper>
            <effort>0</effort>
            <velocity>0</velocity>
          </limit>
          <dynamics>
            <spring_reference>0</spring_reference>
            <spring_stiffness>0</spring_stiffness>
          </dynamics>
        </axis>
      </joint>
      <link name='bluerov2/pose_sensor_link_default'>
        <pose relative_to='bluerov2/pose_sensor_default_joint'>0 0 0 0 -0 0</pose>
        <inertial>
          <pose>0 0 0 0 -0 0</pose>
          <mass>0.001</mass>
          <inertia>
            <ixx>1e-05</ixx>
            <ixy>0</ixy>
            <ixz>0</ixz>
            <iyy>1e-05</iyy>
            <iyz>0</iyz>
            <izz>1e-05</izz>
          </inertia>
        </inertial>
        <self_collide>0</self_collide>
        <enable_wind>0</enable_wind>
        <kinematic>0</kinematic>
      </link>
      <joint name='bluerov2/pressure_joint' type='revolute'>
        <pose relative_to='bluerov2/base_link'>0 0 0 0 -0 0</pose>
        <parent>bluerov2/base_link</parent>
        <child>bluerov2/pressure_link</child>
        <axis>
          <xyz>1 0 0</xyz>
          <limit>
            <lower>0</lower>
            <upper>0</upper>
            <effort>0</effort>
            <velocity>0</velocity>
          </limit>
          <dynamics>
            <spring_reference>0</spring_reference>
            <spring_stiffness>0</spring_stiffness>
          </dynamics>
        </axis>
      </joint>
      <link name='bluerov2/pressure_link'>
        <pose relative_to='bluerov2/pressure_joint'>0 0 0 0 -0 0</pose>
        <inertial>
          <pose>0 0 0 0 -0 0</pose>
          <mass>0.015</mass>
          <inertia>
            <ixx>1e-05</ixx>
            <ixy>0</ixy>
            <ixz>0</ixz>
            <iyy>1e-05</iyy>
            <iyz>0</iyz>
            <izz>1e-05</izz>
          </inertia>
        </inertial>
        <collision name='bluerov2/pressure_link_collision'>
          <pose>0 0 0 3.14159 1.57079 3.14159</pose>
          <geometry>
            <cylinder>
              <length>1e-06</length>
              <radius>1e-06</radius>
            </cylinder>
          </geometry>
          <max_contacts>10</max_contacts>
          <surface>
            <contact>
              <ode/>
            </contact>
            <bounce/>
            <friction>
              <torsional>
                <ode/>
              </torsional>
              <ode/>
            </friction>
          </surface>
        </collision>
        <visual name='bluerov2/pressure_link_visual'>
          <pose>0 0 0 0 -0 0</pose>
          <geometry>
            <mesh>
              <scale>1 1 1</scale>
              <uri>file:///home/ubuntu/34763-autonomous-marine-robotics/ros_ws/src/uuv_simulator/uuv_sensor_plugins/uuv_sensor_ros_plugins/meshes/pressure.dae</uri>
            </mesh>
          </geometry>
        </visual>
        <self_collide>0</self_collide>
        <enable_wind>0</enable_wind>
        <kinematic>0</kinematic>
      </link>
      <joint name='bluerov2/thruster_0_joint' type='revolute'>
        <pose relative_to='bluerov2/base_link'>0.1355 -0.1 -0.0725 0 -0 0.785398</pose>
        <parent>bluerov2/base_link</parent>
        <child>bluerov2/thruster_0</child>
        <axis>
          <xyz>1 0 0</xyz>
          <limit>
            <lower>-1e+16</lower>
            <upper>1e+16</upper>
          </limit>
          <dynamics>
            <spring_reference>0</spring_reference>
            <spring_stiffness>0</spring_stiffness>
          </dynamics>
        </axis>
      </joint>
      <link name='bluerov2/thruster_0'>
        <pose relative_to='bluerov2/thruster_0_joint'>0 0 0 0 -0 0</pose>
        <inertial>
          <pose>0 0 0 0 -0 0</pose>
          <mass>0.01</mass>
          <inertia>
            <ixx>1.7e-08</ixx>
            <ixy>0</ixy>
            <ixz>0</ixz>
            <iyy>1.7e-08</iyy>
            <iyz>0</iyz>
            <izz>1.7e-08</izz>
          </inertia>
        </inertial>
        <visual name='bluerov2/thruster_0_visual'>
          <pose>0 0 0 0 -0 0</pose>
          <geometry>
            <mesh>
              <scale>1 1 1</scale>
              <uri>file:///home/ubuntu/34763-autonomous-marine-robotics/ros_ws/src/bluerov2/bluerov2_description/meshes/bluerov2_propcw.dae</uri>
            </mesh>
          </geometry>
        </visual>
        <self_collide>0</self_collide>
        <enable_wind>0</enable_wind>
        <kinematic>0</kinematic>
      </link>
      <joint name='bluerov2/thruster_1_joint' type='revolute'>
        <pose relative_to='bluerov2/base_link'>0.1355 0.1 -0.0725 0 0 -0.785398</pose>
        <parent>bluerov2/base_link</parent>
        <child>bluerov2/thruster_1</child>
        <axis>
          <xyz>1 0 0</xyz>
          <limit>
            <lower>-1e+16</lower>
            <upper>1e+16</upper>
          </limit>
          <dynamics>
            <spring_reference>0</spring_reference>
            <spring_stiffness>0</spring_stiffness>
          </dynamics>
        </axis>
      </joint>
      <link name='bluerov2/thruster_1'>
        <pose relative_to='bluerov2/thruster_1_joint'>0 0 0 0 -0 0</pose>
        <inertial>
          <pose>0 0 0 0 -0 0</pose>
          <mass>0.01</mass>
          <inertia>
            <ixx>1.7e-08</ixx>
            <ixy>0</ixy>
            <ixz>0</ixz>
            <iyy>1.7e-08</iyy>
            <iyz>0</iyz>
            <izz>1.7e-08</izz>
          </inertia>
        </inertial>
        <visual name='bluerov2/thruster_1_visual'>
          <pose>0 0 0 0 -0 0</pose>
          <geometry>
            <mesh>
              <scale>1 1 1</scale>
              <uri>file:///home/ubuntu/34763-autonomous-marine-robotics/ros_ws/src/bluerov2/bluerov2_description/meshes/bluerov2_propcw.dae</uri>
            </mesh>
          </geometry>
        </visual>
        <self_collide>0</self_collide>
        <enable_wind>0</enable_wind>
        <kinematic>0</kinematic>
      </link>
      <joint name='bluerov2/thruster_2_joint' type='revolute'>
        <pose relative_to='bluerov2/base_link'>-0.1475 -0.1 -0.0725 0 -0 2.35619</pose>
        <parent>bluerov2/base_link</parent>
        <child>bluerov2/thruster_2</child>
        <axis>
          <xyz>1 0 0</xyz>
          <limit>
            <lower>-1e+16</lower>
            <upper>1e+16</upper>
          </limit>
          <dynamics>
            <spring_reference>0</spring_reference>
            <spring_stiffness>0</spring_stiffness>
          </dynamics>
        </axis>
      </joint>
      <link name='bluerov2/thruster_2'>
        <pose relative_to='bluerov2/thruster_2_joint'>0 0 0 0 -0 0</pose>
        <inertial>
          <pose>0 0 0 0 -0 0</pose>
          <mass>0.01</mass>
          <inertia>
            <ixx>1.7e-08</ixx>
            <ixy>0</ixy>
            <ixz>0</ixz>
            <iyy>1.7e-08</iyy>
            <iyz>0</iyz>
            <izz>1.7e-08</izz>
          </inertia>
        </inertial>
        <visual name='bluerov2/thruster_2_visual'>
          <pose>0 0 0 0 -0 0</pose>
          <geometry>
            <mesh>
              <scale>1 1 1</scale>
              <uri>file:///home/ubuntu/34763-autonomous-marine-robotics/ros_ws/src/bluerov2/bluerov2_description/meshes/bluerov2_propcw.dae</uri>
            </mesh>
          </geometry>
        </visual>
        <self_collide>0</self_collide>
        <enable_wind>0</enable_wind>
        <kinematic>0</kinematic>
      </link>
      <joint name='bluerov2/thruster_3_joint' type='revolute'>
        <pose relative_to='bluerov2/base_link'>-0.1475 0.1 -0.0725 0 0 -2.35619</pose>
        <parent>bluerov2/base_link</parent>
        <child>bluerov2/thruster_3</child>
        <axis>
          <xyz>1 0 0</xyz>
          <limit>
            <lower>-1e+16</lower>
            <upper>1e+16</upper>
          </limit>
          <dynamics>
            <spring_reference>0</spring_reference>
            <spring_stiffness>0</spring_stiffness>
          </dynamics>
        </axis>
      </joint>
      <link name='bluerov2/thruster_3'>
        <pose relative_to='bluerov2/thruster_3_joint'>0 0 0 0 -0 0</pose>
        <inertial>
          <pose>0 0 0 0 -0 0</pose>
          <mass>0.01</mass>
          <inertia>
            <ixx>1.7e-08</ixx>
            <ixy>0</ixy>
            <ixz>0</ixz>
            <iyy>1.7e-08</iyy>
            <iyz>0</iyz>
            <izz>1.7e-08</izz>
          </inertia>
        </inertial>
        <visual name='bluerov2/thruster_3_visual'>
          <pose>0 0 0 0 -0 0</pose>
          <geometry>
            <mesh>
              <scale>1 1 1</scale>
              <uri>file:///home/ubuntu/34763-autonomous-marine-robotics/ros_ws/src/bluerov2/bluerov2_description/meshes/bluerov2_propcw.dae</uri>
            </mesh>
          </geometry>
        </visual>
        <self_collide>0</self_collide>
        <enable_wind>0</enable_wind>
        <kinematic>0</kinematic>
      </link>
      <joint name='bluerov2/thruster_4_joint' type='revolute'>
        <pose relative_to='bluerov2/base_link'>0.0025 -0.1105 -0.005 3.14159 -1.57079 3.14159</pose>
        <parent>bluerov2/base_link</parent>
        <child>bluerov2/thruster_4</child>
        <axis>
          <xyz>1 0 0</xyz>
          <limit>
            <lower>-1e+16</lower>
            <upper>1e+16</upper>
          </limit>
          <dynamics>
            <spring_reference>0</spring_reference>
            <spring_stiffness>0</spring_stiffness>
          </dynamics>
        </axis>
      </joint>
      <link name='bluerov2/thruster_4'>
        <pose relative_to='bluerov2/thruster_4_joint'>0 0 0 0 -0 0</pose>
        <inertial>
          <pose>0 0 0 0 -0 0</pose>
          <mass>0.01</mass>
          <inertia>
            <ixx>1.7e-08</ixx>
            <ixy>0</ixy>
            <ixz>0</ixz>
            <iyy>1.7e-08</iyy>
            <iyz>0</iyz>
            <izz>1.7e-08</izz>
          </inertia>
        </inertial>
        <visual name='bluerov2/thruster_4_visual'>
          <pose>0 0 0 0 -0 0</pose>
          <geometry>
            <mesh>
              <scale>1 1 1</scale>
              <uri>file:///home/ubuntu/34763-autonomous-marine-robotics/ros_ws/src/bluerov2/bluerov2_description/meshes/bluerov2_propcw.dae</uri>
            </mesh>
          </geometry>
        </visual>
        <self_collide>0</self_collide>
        <enable_wind>0</enable_wind>
        <kinematic>0</kinematic>
      </link>
      <joint name='bluerov2/thruster_5_joint' type='revolute'>
        <pose relative_to='bluerov2/base_link'>0.0025 0.1105 -0.005 3.14159 -1.57079 3.14159</pose>
        <parent>bluerov2/base_link</parent>
        <child>bluerov2/thruster_5</child>
        <axis>
          <xyz>1 0 0</xyz>
          <limit>
            <lower>-1e+16</lower>
            <upper>1e+16</upper>
          </limit>
          <dynamics>
            <spring_reference>0</spring_reference>
            <spring_stiffness>0</spring_stiffness>
          </dynamics>
        </axis>
      </joint>
      <link name='bluerov2/thruster_5'>
        <pose relative_to='bluerov2/thruster_5_joint'>0 0 0 0 -0 0</pose>
        <inertial>
          <pose>0 0 0 0 -0 0</pose>
          <mass>0.01</mass>
          <inertia>
            <ixx>1.7e-08</ixx>
            <ixy>0</ixy>
            <ixz>0</ixz>
            <iyy>1.7e-08</iyy>
            <iyz>0</iyz>
            <izz>1.7e-08</izz>
          </inertia>
        </inertial>
        <visual name='bluerov2/thruster_5_visual'>
          <pose>0 0 0 0 -0 0</pose>
          <geometry>
            <mesh>
              <scale>1 1 1</scale>
              <uri>file:///home/ubuntu/34763-autonomous-marine-robotics/ros_ws/src/bluerov2/bluerov2_description/meshes/bluerov2_propcw.dae</uri>
            </mesh>
          </geometry>
        </visual>
        <self_collide>0</self_collide>
        <enable_wind>0</enable_wind>
        <kinematic>0</kinematic>
      </link>
      <joint name='bluerov2_sonarforward_joint' type='revolute'>
        <pose relative_to='bluerov2/base_link'>0.2 0 -0.05 0 -0 0</pose>
        <parent>bluerov2/base_link</parent>
        <child>bluerov2/sonarforward_link</child>
        <axis>
          <xyz>1 0 0</xyz>
          <limit>
            <lower>0</lower>
            <upper>0</upper>
            <effort>0</effort>
            <velocity>0</velocity>
          </limit>
          <dynamics>
            <spring_reference>0</spring_reference>
            <spring_stiffness>0</spring_stiffness>
          </dynamics>
        </axis>
      </joint>
      <link name='bluerov2/sonarforward_link'>
        <pose relative_to='bluerov2_sonarforward_joint'>0 0 0 0 -0 0</pose>
        <inertial>
          <pose>0 0 0 0 -0 0</pose>
          <mass>0.1</mass>
          <inertia>
            <ixx>1e-05</ixx>
            <ixy>0</ixy>
            <ixz>0</ixz>
            <iyy>1e-05</iyy>
            <iyz>0</iyz>
            <izz>1e-05</izz>
          </inertia>
        </inertial>
        <collision name='bluerov2/sonarforward_link_collision'>
          <pose>0 0 0 3.14159 1.57079 3.14159</pose>
          <geometry>
            <cylinder>
              <length>1e-06</length>
              <radius>1e-06</radius>
            </cylinder>
          </geometry>
          <surface>
            <contact>
              <ode/>
            </contact>
            <friction>
              <ode/>
              <torsional>
                <ode/>
              </torsional>
            </friction>
            <bounce/>
          </surface>
          <max_contacts>10</max_contacts>
        </collision>
        <visual name='bluerov2/sonarforward_link_visual'>
          <pose>0.2 0 -0.05 0 -0 0</pose>
          <geometry>
            <box>
              <size>0.1 0.1 0.1</size>
            </box>
          </geometry>
        </visual>
        <sensor name='sonarforward' type='ray'>
          <pose>0 0 0 0 -0 0</pose>
          <visualize>1</visualize>
          <update_rate>15</update_rate>
          <ray>
            <scan>
              <horizontal>
                <samples>100</samples>
                <resolution>1</resolution>
                <min_angle>-1.135</min_angle>
                <max_angle>1.135</max_angle>
              </horizontal>
              <vertical>
                <samples>1</samples>
                <min_angle>0</min_angle>
                <max_angle>0</max_angle>
              </vertical>
            </scan>
            <range>
              <min>0.1</min>
              <max>1000</max>
              <resolution>0.01</resolution>
            </range>
            <noise>
              <type>gaussian</type>
              <mean>0</mean>
              <stddev>0.27</stddev>
            </noise>
          </ray>
          <plugin name='sonarforward_controller' filename='libgazebo_ros_laser.so'>
            <topicName>sonar_forward</topicName>
            <frameName>bluerov2/sonarforward_link</frameName>
            <robotNamespace>/bluerov2/</robotNamespace>
          </plugin>
        </sensor>
        <self_collide>0</self_collide>
        <enable_wind>0</enable_wind>
        <kinematic>0</kinematic>
      </link>
      <plugin name='uuv_plugin' filename='libuuv_underwater_object_ros_plugin.so'>
        <fluid_density>1028.0</fluid_density>
        <flow_velocity_topic>hydrodynamics/current_velocity</flow_velocity_topic>
        <debug>0</debug>
        <link name='bluerov2/base_link'>
          <neutrally_buoyant>0</neutrally_buoyant>
          <volume>0.011054</volume>
          <box>
            <width>0.448</width>
            <length>0.2384</length>
            <height>0.28066</height>
          </box>
          <center_of_buoyancy>0 0 0.3872</center_of_buoyancy>
          <hydrodynamic_model>
            <type>fossen</type>
            <added_mass>1.7182 0 0 0 0 0 0 0 0 0 0 0 0 0 5.468 0 0 0 0 0 0 0 0 0 0 0 0 0 1.2481 0 0 0 0 0 0 0.4006</added_mass>
            <linear_damping>-11.7391 -20 -31.8678 -25 -44.9085 -5</linear_damping>
            <quadratic_damping>-12.18 -21.66 -36.99 -1.55 -1.55 -1.55</quadratic_damping>
          </hydrodynamic_model>
        </link>
        <robotNamespace>/bluerov2/</robotNamespace>
      </plugin>
      <plugin name='bluerov2_0_thruster_model' filename='libuuv_thruster_ros_plugin.so'>
        <linkName>bluerov2/thruster_0</linkName>
        <jointName>bluerov2/thruster_0_joint</jointName>
        <thrusterID>0</thrusterID>
        <gain>1</gain>
        <thrust_efficiency>1</thrust_efficiency>
        <propeller_efficiency>1</propeller_efficiency>
        <dynamics>
          <type>FirstOrder</type>
          <timeConstant>0.2</timeConstant>
        </dynamics>
        <conversion>
          <type>Basic</type>
          <rotorConstant>0.0001</rotorConstant>
        </conversion>
        <robotNamespace>/bluerov2/</robotNamespace>
      </plugin>
      <plugin name='bluerov2_1_thruster_model' filename='libuuv_thruster_ros_plugin.so'>
        <linkName>bluerov2/thruster_1</linkName>
        <jointName>bluerov2/thruster_1_joint</jointName>
        <thrusterID>1</thrusterID>
        <gain>1</gain>
        <thrust_efficiency>1</thrust_efficiency>
        <propeller_efficiency>1</propeller_efficiency>
        <dynamics>
          <type>FirstOrder</type>
          <timeConstant>0.2</timeConstant>
        </dynamics>
        <conversion>
          <type>Basic</type>
          <rotorConstant>0.0001</rotorConstant>
        </conversion>
        <robotNamespace>/bluerov2/</robotNamespace>
      </plugin>
      <plugin name='bluerov2_2_thruster_model' filename='libuuv_thruster_ros_plugin.so'>
        <linkName>bluerov2/thruster_2</linkName>
        <jointName>bluerov2/thruster_2_joint</jointName>
        <thrusterID>2</thrusterID>
        <gain>1</gain>
        <thrust_efficiency>1</thrust_efficiency>
        <propeller_efficiency>1</propeller_efficiency>
        <dynamics>
          <type>FirstOrder</type>
          <timeConstant>0.2</timeConstant>
        </dynamics>
        <conversion>
          <type>Basic</type>
          <rotorConstant>0.0001</rotorConstant>
        </conversion>
        <robotNamespace>/bluerov2/</robotNamespace>
      </plugin>
      <plugin name='bluerov2_3_thruster_model' filename='libuuv_thruster_ros_plugin.so'>
        <linkName>bluerov2/thruster_3</linkName>
        <jointName>bluerov2/thruster_3_joint</jointName>
        <thrusterID>3</thrusterID>
        <gain>1</gain>
        <thrust_efficiency>1</thrust_efficiency>
        <propeller_efficiency>1</propeller_efficiency>
        <dynamics>
          <type>FirstOrder</type>
          <timeConstant>0.2</timeConstant>
        </dynamics>
        <conversion>
          <type>Basic</type>
          <rotorConstant>0.0001</rotorConstant>
        </conversion>
        <robotNamespace>/bluerov2/</robotNamespace>
      </plugin>
      <plugin name='bluerov2_4_thruster_model' filename='libuuv_thruster_ros_plugin.so'>
        <linkName>bluerov2/thruster_4</linkName>
        <jointName>bluerov2/thruster_4_joint</jointName>
        <thrusterID>4</thrusterID>
        <gain>1</gain>
        <thrust_efficiency>1</thrust_efficiency>
        <propeller_efficiency>1</propeller_efficiency>
        <dynamics>
          <type>FirstOrder</type>
          <timeConstant>0.2</timeConstant>
        </dynamics>
        <conversion>
          <type>Basic</type>
          <rotorConstant>0.0001</rotorConstant>
        </conversion>
        <robotNamespace>/bluerov2/</robotNamespace>
      </plugin>
      <plugin name='bluerov2_5_thruster_model' filename='libuuv_thruster_ros_plugin.so'>
        <linkName>bluerov2/thruster_5</linkName>
        <jointName>bluerov2/thruster_5_joint</jointName>
        <thrusterID>5</thrusterID>
        <gain>1</gain>
        <thrust_efficiency>1</thrust_efficiency>
        <propeller_efficiency>1</propeller_efficiency>
        <dynamics>
          <type>FirstOrder</type>
          <timeConstant>0.2</timeConstant>
        </dynamics>
        <conversion>
          <type>Basic</type>
          <rotorConstant>0.0001</rotorConstant>
        </conversion>
        <robotNamespace>/bluerov2/</robotNamespace>
      </plugin>
      <plugin name='pose_3d_plugin' filename='libuuv_gazebo_ros_pose_gt_plugin.so'>
        <robot_namespace>bluerov2</robot_namespace>
        <link_name>bluerov2/base_link</link_name>
        <sensor_topic>pose_gt</sensor_topic>
        <static_reference_frame>world</static_reference_frame>
        <noise_sigma>0.0</noise_sigma>
        <noise_amplitude>0.0</noise_amplitude>
        <update_rate>20</update_rate>
        <enable_gazebo_messages>0</enable_gazebo_messages>
        <publish_ned_odom>0</publish_ned_odom>
        <robotNamespace>/bluerov2/</robotNamespace>
      </plugin>
      <plugin name='libuuv_gazebo_imu_plugin' filename='libuuv_gazebo_ros_imu_plugin.so'>
        <robot_namespace>bluerov2</robot_namespace>
        <link_name>bluerov2/imu_link</link_name>
        <sensor_topic>imu</sensor_topic>
        <gyroscope_noise_density>0.003394</gyroscope_noise_density>
        <gyroscope_random_walk>0.00038785</gyroscope_random_walk>
        <gyroscope_bias_correlation_time>1000.0</gyroscope_bias_correlation_time>
        <gyroscope_turn_on_bias_sigma>0.087</gyroscope_turn_on_bias_sigma>
        <accelerometer_noise_density>0.04</accelerometer_noise_density>
        <accelerometer_random_walk>0.06</accelerometer_random_walk>
        <accelerometer_bias_correlation_time>300.0</accelerometer_bias_correlation_time>
        <accelerometer_turn_on_bias_sigma>0.196</accelerometer_turn_on_bias_sigma>
        <orientation_noise>0.03</orientation_noise>
        <update_rate>50</update_rate>
        <enable_gazebo_messages>0</enable_gazebo_messages>
        <enable_local_ned_frame>0</enable_local_ned_frame>
        <static_reference_frame>world</static_reference_frame>
        <robotNamespace>/bluerov2/</robotNamespace>
      </plugin>
      <plugin name='libuuv_gazebo_subseapressure_plugin' filename='libuuv_gazebo_ros_subsea_pressure_plugin.so'>
        <robot_namespace>bluerov2</robot_namespace>
        <link_name>bluerov2/pressure_link</link_name>
        <sensor_topic>pressure</sensor_topic>
        <update_rate>10</update_rate>
        <saturation>30000</saturation>
        <noise_sigma>3.0</noise_sigma>
        <noise_amplitude>0.0</noise_amplitude>
        <estimate_depth_on>0</estimate_depth_on>
        <standard_pressure>101.325</standard_pressure>
        <kPa_per_meter>9.80638</kPa_per_meter>
        <enable_gazebo_messages>0</enable_gazebo_messages>
        <robotNamespace>/bluerov2/</robotNamespace>
      </plugin>
      <static>0</static>
      <plugin name='uuv_joint_state_publisher' filename='libuuv_joint_state_publisher.so'>
        <robotNamespace>bluerov2</robotNamespace>
        <updateRate>10</updateRate>
      </plugin>
      <pose>0 0 -34 0 -0 0</pose>
    </model>
  </world>
</sdf>
